2025-06-16 14:27:45.439 Uncaught app execution
Traceback (most recent call last):
  File "/home/runner/workspace/.pythonlibs/lib/python3.11/site-packages/streamlit/runtime/scriptrunner/exec_code.py", line 121, in exec_func_with_error_handling
    result = func()
             ^^^^^^
  File "/home/runner/workspace/.pythonlibs/lib/python3.11/site-packages/streamlit/runtime/scriptrunner/script_runner.py", line 645, in code_to_exec
    exec(code, module.__dict__)
  File "/home/runner/workspace/app.py", line 492, in <module>
    main()
  File "/home/runner/workspace/app.py", line 478, in main
    render_transaction_details_view(data_mgr, ai_cat, audit_log)
  File "/home/runner/workspace/app.py", line 209, in render_transaction_details_view
    (pd.to_datetime(filtered_df['date']) >= pd.to_datetime(start_date)) &
     ^^^^^^^^^^^^^^^^^^^^^^^^^^^^^^^^^^^
  File "/home/runner/workspace/.pythonlibs/lib/python3.11/site-packages/pandas/core/tools/datetimes.py", line 1068, in to_datetime
    cache_array = _maybe_cache(arg, format, cache, convert_listlike)
                  ^^^^^^^^^^^^^^^^^^^^^^^^^^^^^^^^^^^^^^^^^^^^^^^^^^
  File "/home/runner/workspace/.pythonlibs/lib/python3.11/site-packages/pandas/core/tools/datetimes.py", line 249, in _maybe_cache
    cache_dates = convert_listlike(unique_dates, format)
                  ^^^^^^^^^^^^^^^^^^^^^^^^^^^^^^^^^^^^^^
  File "/home/runner/workspace/.pythonlibs/lib/python3.11/site-packages/pandas/core/tools/datetimes.py", line 435, in _convert_listlike_datetimes
    return _array_strptime_with_fallback(arg, name, utc, format, exact, errors)
           ^^^^^^^^^^^^^^^^^^^^^^^^^^^^^^^^^^^^^^^^^^^^^^^^^^^^^^^^^^^^^^^^^^^^
  File "/home/runner/workspace/.pythonlibs/lib/python3.11/site-packages/pandas/core/tools/datetimes.py", line 469, in _array_strptime_with_fallback
    result, tz_out = array_strptime(arg, fmt, exact=exact, errors=errors, utc=utc)
                     ^^^^^^^^^^^^^^^^^^^^^^^^^^^^^^^^^^^^^^^^^^^^^^^^^^^^^^^^^^^^^
  File "pandas/_libs/tslibs/strptime.pyx", line 501, in pandas._libs.tslibs.strptime.array_strptime
  File "pandas/_libs/tslibs/strptime.pyx", line 451, in pandas._libs.tslibs.strptime.array_strptime
  File "pandas/_libs/tslibs/strptime.pyx", line 583, in pandas._libs.tslibs.strptime._parse_with_format
ValueError: time data "13-08-2023" doesn't match format "%m-%d-%Y", at position 5. You might want to try:
    - passing `format` if your strings have a consistent format;
    - passing `format='ISO8601'` if your strings are all ISO8601 but not necessarily in exactly the same format;
    - passing `format='mixed'`, and the format will be inferred for each element individually. You might want to use `dayfirst` alongside this.